Workbook

Sheet LP-OCIP Failure Summary – April
A1: LP-OCIP Failure Summary – April to September _2026
B3: LP-OCIP | C3: Total inspection Quantity | D3: Total Accepted Quantity | E3: Total Defect Quantity | F3: FTR % | G3: Defect % | I3: Category of the problem | J3: Defect Quantity | K3: Cumulative Quantity | L3: Cumulative (%) | M3: Defect Contribution (%)
B4: TYPE OF MODULE | C4: =SUM(C5:C9) -> 2055 | D4: =SUM(D5:D9) -> 1585 | E4: =SUM(E5:E9) -> 470 | F4: =D4/C4 -> 0.77128954 | G4: =E4/C4 -> 0.22871046 | I4: Assembly Errors | J4: 246 | K4: =J4 -> 246 | L4: =K4/$K$6 -> 0.52340426 | M4: =J4/$K$6 -> 0.52340426
B5: LP-OCIP (DMI) CCB_E70_EF12 | C5: 1822 | D5: 1406 | E5: 416 | F5: =D5/C5 -> 0.77167947 | G5: =E5/C5 -> 0.22832053 | I5: Functional issues | J5: 216 | K5: =K4+J5 -> 462 | L5: =K5/$K$6 -> 0.98297872 | M5: =J5/$K$6 -> 0.45957447
B6: LP-OCIP (DMI) Conventional EMU | C6: 135 | D6: 102 | E6: 33 | F6: =D6/C6 -> 0.75555556 | G6: =E6/C6 -> 0.24444444 | I6: Damages | J6: 8 | K6: =K5+J6 -> 470 | L6: =K6/$K$6 -> 1 | M6: =J6/$K$6 -> 0.017021277
B7: LP-OCIP(3PH)EMU | C7: 58 | D7: 44 | E7: 14 | F7: =D7/C7 -> 0.75862069 | G7: =E7/C7 -> 0.24137931
B8: LP-OCIP (DMI) AMRIT BHARAT | C8: 33 | D8: 29 | E8: 4 | F8: =D8/C8 -> 0.87878788 | G8: =E8/C8 -> 0.12121212
B9: LP-OCIP (DMI) TRAIN-18 | C9: 7 | D9: 4 | E9: 3 | F9: =D9/C9 -> 0.57142857 | G9: =E9/C9 -> 0.42857143
B12: Sub Category of the problem | C12: No of issues Quantity | D12: Cumulative Quantity | E12: Cumulative (%) | F12: Defect Contribution (%)
B13: Loose fitment | C13: 122 | D13: 122 | E13: =D13/$D$27 -> 0.25957447 | F13: =C13/$D$27 -> 0.25957447
B14: Display issue | C14: 94 | D14: =D13+C14 -> 216 | E14: =D14/$D$27 -> 0.45957447 | F14: =C14/$D$27 -> 0.2
B15: Defect component | C15: 61 | D15: =D14+C15 -> 277 | E15: =D15/$D$27 -> 0.5893617 | F15: =C15/$D$27 -> 0.12978723
B16: Missing operation | C16: 52 | D16: =D15+C16 -> 329 | E16: =D16/$D$27 -> 0.7 | F16: =C16/$D$27 -> 0.1106383
B17: Functional issue | C17: 38 | D17: =D16+C17 -> 367 | E17: =D17/$D$27 -> 0.78085106 | F17: =C17/$D$27 -> 0.080851064
B18: Loose connection | C18: 25 | D18: =D17+C18 -> 392 | E18: =D18/$D$27 -> 0.83404255 | F18: =C18/$D$27 -> 0.053191489
B19: Dust | C19: 20 | D19: =D18+C19 -> 412 | E19: =D19/$D$27 -> 0.87659574 | F19: =C19/$D$27 -> 0.042553191
B20: Wire interchanged | C20: 19 | D20: =D19+C20 -> 431 | E20: =D20/$D$27 -> 0.91702128 | F20: =C20/$D$27 -> 0.040425532
B21: Scratches | C21: 15 | D21: =D20+C21 -> 446 | E21: =D21/$D$27 -> 0.94893617 | F21: =C21/$D$27 -> 0.031914894
B22: Carrier board PCBA | C22: 10 | D22: =D21+C22 -> 456 | E22: =D22/$D$27 -> 0.97021277 | F22: =C22/$D$27 -> 0.021276596
B23: Buzzer issue | C23: 5 | D23: =D22+C23 -> 461 | E23: =D23/$D$27 -> 0.98085106 | F23: =C23/$D$27 -> 0.010638298
B24: Power on issue | C24: 4 | D24: =D23+C24 -> 465 | E24: =D24/$D$27 -> 0.9893617 | F24: =C24/$D$27 -> 0.0085106383
B25: Keypad issue | C25: 3 | D25: =D24+C25 -> 468 | E25: =D25/$D$27 -> 0.99574468 | F25: =C25/$D$27 -> 0.0063829787
... B27: Paint peel-off | C27: 1 | D27: =D26+C27 -> 470 | E27: =D27/$D$27 -> 1 | F27: =C27/$D$27 -> 0.0021276596

Sheet LP-OCIP observations (APR-SEP) 
A1: LP-OCIP - IN_HOUSE FAILURES - ANALYSIS
A2: LP-OCIP (APR-SEP) 2026 Failure Report by QC Engineer at Factory
E3: =SUM(E5:E959) -> 2055 | F3: =SUM(F5:F959) -> 1585 | G3: =SUM(G5:G959) -> 470
A4: # | B4: Failure detected Area IPQC | C4: Failure Reported by (Name of QC Eng) | D4: Part Number | E4: Production QTY ( Nos) | F4: Accepted QTY ( Nos) | G4: Rework QTY ( Nos) | H4: Date of occurrence of failures | I4: Name of Failed item (Main, Unit / Module / Sub-module / component) | J4: Sl No of failed item | K4: "Observed Problem (First information Report)" | L4: Root Cause of failure | M4: Action to be taken (Corrective action) | N4: Responsible person | O4: Target Date | P4: Preventive Action | Q4: Responsible person.1 | R4: Target Date.1 | S4: Status (Issue Closed / Open) | T4: Sub Category | U4: Category of Problem | V4: Remarks, if any
A5: 1 | B5: IPQC | C5: D.Srishanth Reddy R.Navaneetha | D5: 6000043167 | E5: 1 | F5: 1 | G5: 0 | H5: 46124 | I5: LP-OCIP (DMI) CCB_E70_EF12 | J5: 516300010426001 | K5: OK | L5: OK | M5: OK | N5: Rajinikanth | Q5: Rajinikanth | S5: Closed | T5: OK | U5: OK
A6: 2 | B6: IPQC | C6: D.Srishanth Reddy R.Navaneetha | D6: 6000043167 | E6: 1 | F6: 0 | G6: 1 | H6: 46124 | I6: LP-OCIP (DMI) CCB_E70_EF12 | J6: 516300010426002 | K6: Wire interchange of Brick board J1 connector and carrier board J19 connector. | L6: Rewire correctly as per schematic and label wires | N6: Rajinikanth | P6: Training should be given to the operator and implement wire labeling system | Q6: Rajinikanth | S6: Closed | T6: Wire Interchanged | U6: Assembly Errors
A7: 3 | B7: IPQC | C7: D.Srishanth Reddy R.Navaneetha | D7: 6000043167 | E7: 5 | F7: 5 | G7: 0 | H7: 46124 | I7: LP-OCIP (DMI) CCB_E70_EF12 | J7: 516300010426003-007 | K7: OK | L7: OK | M7: OK | N7: Rajinikanth | Q7: Rajinikanth | S7: Closed | T7: OK | U7: OK
A8: 4 | B8: IPQC | C8: D.Srishanth Reddy R.Navaneetha | D8: 6000043167 | E8: 2 | F8: 2 | G8: 0 | H8: 46125 | I8: LP-OCIP (DMI) CCB_E70_EF12 | J8: 516300010426008-009 | K8: OK | L8: OK | M8: OK | N8: Rajinikanth | Q8: Rajinikanth | S8: Closed | T8: OK | U8: OK
A9: 5 | B9: IPQC | C9: D.Srishanth Reddy R.Navaneetha | D9: 6000043167 | E9: 1 | F9: 0 | G9: 1 | H9: 46125 | I9: LP-OCIP (DMI) CCB_E70_EF12 | J9: 516300010426010 | K9: Loose fitment MIL Connector MC11 / MC13 Male Connector. | L9: Tightened the connector with the buska tool as per its standards | N9: Rajinikanth | P9: The operator shall use the appropriate tools and equipment, including the Buska tool, as specified in the assembly procedure and follow the manufacturer’s instructions | Q9: Rajinikanth | S9: Closed | T9: Loose Fitment | U9: Assembly Errors
A10: 6 | B10: IPQC | C10: D.Srishanth Reddy R.Navaneetha | D10: 6000043167 | E10: 4 | F10: 4 | G10: 0 | H10: 46125 | I10: LP-OCIP (DMI) CCB_E70_EF12 | J10: 516300010426011-014 | K10: OK | L10: OK | M10: OK | N10: Rajinikanth | Q10: Rajinikanth | S10: Closed | T10: OK | U10: OK
A11: 7 | B11: IPQC | C11: D.Srishanth Reddy R.Navaneetha | D11: 6000043167 | E11: 1 | F11: 0 | G11: 1 | H11: 46125 | I11: LP-OCIP (DMI) CCB_E70_EF12 | J11: 516300010426015 | K11: Harness Loose connection to the SOS push button. | L11: 1.Reworked all defective assemblies and corrected loose/missing parts 2. Conducted 100% inspection before release | N11: Rajinikanth | P11: Provide detailed Procedures/work instructions at workstations | Q11: Rajinikanth | S11: Closed | T11: Loose connection | U11: Assembly Errors
A12: 8 | B12: IPQC | C12: D.Srishanth Reddy R.Navaneetha | D12: 6000043167 | E12: 5 | F12: 5 | G12: 0 | H12: 46125 | I12: LP-OCIP (DMI) CCB_E70_EF12 | J12: 516300010426016-020 | K12: OK | L12: OK | M12: OK | N12: Rajinikanth | Q12: Rajinikanth | S12: Closed | T12: OK | U12: OK
A13: 9 | B13: IPQC | C13: D.Srishanth Reddy | D13: 6000043167 | E13: 1 | F13: 0 | G13: 1 | H13: 46126 | I13: LP-OCIP (DMI) CCB_E70_EF12 | J13: 516300010426021 | K13: Loose fitment Rotary switch. | L13: 1.Reworked all defective assemblies and corrected loose/missing parts. 2. Conducted 100% inspection before release. | N13: Rajinikanth | P13: Provide detailed Procedures/work instructions at workstations | Q13: Rajinikanth | S13: Closed | T13: Loose Fitment | U13: Assembly Errors
A14: 10 | B14: IPQC | C14: D.Srishanth Reddy | D14: 6000043167 | E14: 1 | F14: 0 | G14: 1 | H14: 46126 | I14: LP-OCIP (DMI) CCB_E70_EF12 | J14: 516300010426022 | K14: Loose fitment Rotary switch. | L14: 1.Reworked all defective assemblies and corrected loose/missing parts. 2. Conducted 100% inspection before release. | N14: Rajinikanth | P14: Provide detailed Procedures/work instructions at workstations | Q14: Rajinikanth | S14: Closed | T14: Loose Fitment | U14: Assembly Errors
A15: 11 | B15: IPQC | C15: D.Srishanth Reddy | D15: 6000043167 | E15: 9 | F15: 9 | G15: 0 | H15: 46126 | I15: LP-OCIP (DMI) CCB_E70_EF12 | J15: 516300010426023-031 | K15: OK | L15: OK | M15: OK | N15: Rajinikanth | Q15: Rajinikanth | S15: Closed | T15: OK | U15: OK
A16: 12 | B16: IPQC | C16: D.Srishanth Reddy | D16: 6000043167 | E16: 1 | F16: 0 | G16: 1 | H16: 46126 | I16: LP-OCIP (DMI) CCB_E70_EF12 | J16: 516300010426032 | K16: Harness Loose connection to the Ack Push button. | L16: 1.Reworked all defective assemblies and corrected loose/missing parts 2. Conducted 100% inspection before release | N16: Rajinikanth | P16: Provide detailed Procedures/work instructions at workstations | Q16: Rajinikanth | S16: Closed | T16: Loose connection | U16: Assembly Errors
A17: 13 | B17: IPQC | C17: D.Srishanth Reddy | D17: 6000043167 | E17: 16 | F17: 16 | G17: 0 | H17: 46126 | I17: LP-OCIP (DMI) CCB_E70_EF12 | J17: 516300010426033-048 | K17: OK | L17: OK | M17: OK | N17: Rajinikanth | Q17: Rajinikanth | S17: Closed | T17: OK | U17: OK
A18: 14 | B18: IPQC | C18: D.Srishanth Reddy | D18: 6000043167 | E18: 1 | F18: 0 | G18: 1 | H18: 46126 | I18: LP-OCIP (DMI) CCB_E70_EF12 | J18: 516300010426049 | K18: Scratches on Keypad. | L18: Replaced keypad | N18: Rajinikanth | P18: Train staff on handling procedures | Q18: Rajinikanth | S18: Closed | T18: Scratches | U18: Assembly Errors
A19: 15 | B19: IPQC | C19: D.Srishanth Reddy | D19: 6000043167 | E19: 1 | F19: 0 | G19: 1 | H19: 46126 | I19: LP-OCIP (DMI) CCB_E70_EF12 | J19: 516300010426050 | K19: Green DOT oberved on display. | L19: Replace or repair the faulty display unit. check connections and test functionality post-repair. | N19: Rajinikanth | P19: Ensure proper handling and storage of display components | Q19: Rajinikanth | S19: Closed | T19: Display issue | U19: Functional issue
A20: 16 | B20: IPQC | C20: D.Srishanth Reddy | D20: 6000043167 | E20: 1 | F20: 0 | G20: 1 | H20: 46142 | I20: LP-OCIP (DMI) CCB_E70_EF12 | J20: 516300010426051 | K20: Display Low Brightness. | L20: Replace or repair the faulty display unit. check connections and test functionality post-repair. | N20: Rajinikanth | P20: Ensure proper handling and storage of display components | Q20: Rajinikanth | S20: Closed | T20: Display issue | U20: Functional issue
A21: 17 | B21: IPQC | C21: D.Srishanth Reddy | D21: 6000043167 | E21: 1 | F21: 0 | G21: 1 | H21: 46142 | I21: LP-OCIP (DMI) CCB_E70_EF12 | J21: 516300010426052 | K21: Loose Fitment of M3*20mm LVDS Holder screw. | L21: 1.Reworked all defective assemblies and corrected loose/missing parts. 2. Conducted 100% inspection before release. | N21: Rajinikanth | P21: Provide detailed Procedures/work instructions at workstations | Q21: Rajinikanth | S21: Closed | T21: Loose Fitment | U21: Assembly Errors
A22: 18 | B22: IPQC | C22: D.Srishanth Reddy | D22: 6000043167 | E22: 10 | F22: 10 | G22: 0 | H22: 46142 | I22: LP-OCIP (DMI) CCB_E70_EF12 | J22: 516300010426053-062 | K22: OK | L22: OK | M22: OK | N22: Rajinikanth | Q22: Rajinikanth | S22: Closed | T22: OK | U22: OK
A23: 19 | B23: IPQC | C23: D.Srishanth Reddy | D23: 6000043167 | E23: 1 | F23: 0 | G23: 1 | H23: 46142 | I23: LP-OCIP (DMI) CCB_E70_EF12 | J23: 516300010426063 | K23: Scratches on Display. | L23: Replaced display | N23: Rajinikanth | P23: Train staff on handling procedures | Q23: Rajinikanth | S23: Closed | T23: Scratches | U23: Assembly Errors
A24: 20 | B24: IPQC | C24: D.Srishanth Reddy | D24: 6000043167 | E24: 1 | F24: 0 | G24: 1 | H24: 46142 | I24: LP-OCIP (DMI) CCB_E70_EF12 | J24: 516300010426064 | K24: Keypad keys are NOT working | L24: Replace or repair the keypad faulty unit. check connections and test functionality post-repair. | N24: Rajinikanth | P24: Ensure proper handling and storage of key pad components | Q24: Rajinikanth | S24: Closed | T24: Keypad Issue | U24: Functional issue
A25: 21 | B25: IPQC | C25: D.Srishanth Reddy | D25: 6000043167 | E25: 1 | F25: 1 | G25: 0 | H25: 46142 | I25: LP-OCIP (DMI) CCB_E70_EF12 | J25: 516300010426065 | K25: OK | L25: OK | M25: OK | N25: Rajinikanth | Q25: Rajinikanth | S25: Closed | T25: OK | U25: OK
A26: 22 | B26: IPQC | C26: D.Srishanth Reddy | D26: 6000043167 | E26: 1 | F26: 0 | G26: 1 | H26: 46142 | I26: LP-OCIP (DMI) CCB_E70_EF12 | J26: 516300010426066 | K26: Display Low Brightness. | L26: Replace or repair the faulty display unit. check connections and test functionality post-repair. | N26: Rajinikanth | P26: Ensure proper handling and storage of display components | Q26: Rajinikanth | S26: Closed | T26: Display issue | U26: Functional issue
A27: 23 | B27: IPQC | C27: D.Srishanth Reddy | D27: 6000043167 | E27: 2 | F27: 2 | G27: 0 | H27: 46142 | I27: LP-OCIP (DMI) CCB_E70_EF12 | J27: 516300010426067-068 | K27: OK | L27: OK | M27: OK | N27: Rajinikanth | Q27: Rajinikanth | S27: Closed | T27: OK | U27: OK
A28: 24 | B28: IPQC | C28: D.Srishanth Reddy | D28: 6000043167 | E28: 1 | F28: 0 | G28: 1 | H28: 46146 | I28: LP-OCIP (DMI) CCB_E70_EF12 | J28: 516300010426069 | K28: Wire interchange of HEALTH LED & SOS LED. | L28: Rewire correctly as per schematic and label wires | N28: Rajinikanth | P28: Training should be given to the operator and implement wire labeling system | Q28: Rajinikanth | S28: Closed | T28: Wire Interchanged | U28: Assembly Errors
A29: 25 | B29: IPQC | C29: D.Srishanth Reddy | D29: 6000043167 | E29: 1 | F29: 0 | G29: 1 | H29: 46146 | I29: LP-OCIP (DMI) CCB_E70_EF12 | J29: 516300010426070 | K29: Green DOT oberved on display. | L29: Replace or repair the faulty display unit. check connections and test functionality post-repair. | N29: Rajinikanth | P29: Ensure proper handling and storage of display components | Q29: Rajinikanth | S29: Closed | T29: Display issue | U29: Functional issue
A30: 26 | B30: IPQC | C30: D.Srishanth Reddy | D30: 6000043167 | E30: 1 | F30: 0 | G30: 1 | H30: 46146 | I30: LP-OCIP (DMI) CCB_E70_EF12 | J30: 516300010426071 | K30: Wire interchange of HEALTH LED & SOS LED. | L30: Rewire correctly as per schematic and label wires | N30: Rajinikanth | P30: Training should be given to the operator and implement wire labeling system | Q30: Rajinikanth | S30: Closed | T30: Wire Interchanged | U30: Assembly Errors
A31: 27 | B31: IPQC | C31: D.Srishanth Reddy | D31: 6000043167 | E31: 7 | F31: 7 | G31: 0 | H31: 46146 | I31: LP-OCIP (DMI) CCB_E70_EF12 | J31: 516300010426072-078 | K31: OK | L31: OK | M31: OK | N31: Rajinikanth | Q31: Rajinikanth | S31: Closed | T31: OK | U31: OK
A32: 28 | B32: IPQC | C32: D.Srishanth Reddy | D32: 6000043167 | E32: 2 | F32: 2 | G32: 0 | H32: 46153 | I32: LP-OCIP (DMI) CCB_E70_EF12 | J32: 516300010426079-080 | K32: OK | L32: OK | M32: OK | N32: Rajinikanth | Q32: Rajinikanth | S32: Closed | T32: OK | U32: OK
A33: 29 | B33: IPQC | C33: D.Srishanth Reddy | D33: 6000043167 | E33: 12 | F33: 12 | G33: 0 | H33: 46156 | I33: LP-OCIP (DMI) CCB_E70_EF12 | J33: 516300010526081-092 | K33: OK | L33: OK | M33: OK | N33: Rajinikanth | Q33: Rajinikanth | S33: Closed | T33: OK | U33: OK
A34: 30 | B34: IPQC | C34: D.Srishanth Reddy | D34: 6000043167 | E34: 1 | F34: 0 | G34: 1 | H34: 46156 | I34: LP-OCIP (DMI) CCB_E70_EF12 | J34: 516300010526093 | K34: Harness NOT connected to CANCEL push button switch. | L34: Faulty components were replaced with correct one. | N34: Rajinikanth | P34: 1. Implemented the module Level functional testing for Critical Modules. 2. Introduce quality gate approval before dispatch. 3. Strengthen SOP adherence and process monitoring. | Q34: Rajinikanth | S34: Closed | T34: Missing Operation | U34: Assembly Errors
A35: 31 | B35: IPQC | C35: D.Srishanth Reddy | D35: 6000043167 | E35: 9 | F35: 9 | G35: 0 | H35: 46156 | I35: LP-OCIP (DMI) CCB_E70_EF12 | J35: 516300010526094-102 | K35: OK | L35: OK | M35: OK | N35: Rajinikanth | Q35: Rajinikanth | S35: Closed | T35: OK | U35: OK
A36: 32 | B36: IPQC | C36: D.Srishanth Reddy | D36: 6000043167 | E36: 20 | F36: 20 | G36: 0 | H36: 46157 | I36: LP-OCIP (DMI) CCB_E70_EF12 | J36: 516300010526103-122 | K36: OK | L36: OK | M36: OK | N36: Rajinikanth | Q36: Rajinikanth | S36: Closed | T36: OK | U36: OK
A37: 33 | B37: IPQC | C37: D.Srishanth Reddy | D37: 6000043167 | E37: 2 | F37: 2 | G37: 0 | H37: 46158 | I37: LP-OCIP (DMI) CCB_E70_EF12 | J37: 516300010526123-124 | K37: OK | L37: OK | M37: OK | N37: Rajinikanth | Q37: Rajinikanth | S37: Closed | T37: OK | U37: OK
A38: 34 | B38: IPQC | C38: D.Srishanth Reddy | D38: 6000043167 | E38: 2 | F38: 2 | G38: 0 | H38: 46160 | I38: LP-OCIP (DMI) CCB_E70_EF12 | J38: 516300010526125-126 | K38: OK | L38: OK | M38: OK | N38: Rajinikanth | Q38: Rajinikanth | S38: Closed | T38: OK | U38: OK
A39: 35 | B39: IPQC | C39: D.Srishanth Reddy | D39: 6000043167 | E39: 1 | F39: 0 | G39: 1 | H39: 46170 | I39: LP-OCIP (DMI) CCB_E70_EF12 | J39: 516300010526127 | K39: Loose fitment of M3*10mm Brick board PCBA screw. | L39: 1.Reworked all defective assemblies and corrected loose/missing parts. 2. Conducted 100% inspection before release. | N39: Rajinikanth | P39: Provide detailed Procedures/work instructions at workstations | Q39: Rajinikanth | S39: Closed | T39: Loose Fitment | U39: Assembly Errors
A40: 36 | B40: IPQC | C40: D.Srishanth Reddy | D40: 6000043167 | E40: 2 | F40: 2 | G40: 0 | H40: 46170 | I40: LP-OCIP (DMI) CCB_E70_EF12 | J40: 516300010526128-129 | K40: OK | L40: OK | M40: OK | N40: Rajinikanth | Q40: Rajinikanth | S40: Closed | T40: OK | U40: OK
...

Sheet SUMMARY -  MINI LOCO
A2: MINI LOCO Failure Summary – April to September _2026
B4: LOCO | C4: Total inspection Quantity | D4: Total Accepted Quantity | E4: Total Defect Quantity | F4: FTR% | G4: Defect % | I4: Category of the problem | J4: Defect QTY | K4: Cumulative QTY | L4: Cumulative (%) | M4: Defect Contribution (%)
B5: TYPE OF MODULE | C5: =SUM('MINI LOCO DATA APR - SEPT 2026'!F4:F422) -> 1413 | D5: =SUM('MINI LOCO DATA APR - SEPT 2026'!G4:G422) -> 1246 | E5: =SUM('MINI LOCO DATA APR - SEPT 2026'!H4:H422) -> 167 | F5: =D5/C5 -> 0.88181175 | G5: =E5/C5 -> 0.11818825 | I5: Assembly Errors | J5: 160 | K5: =J5 -> 160 | L5: =K5/$K$6 -> 0.90909091 | M5: =J5/$K$6 -> 0.90909091
B6: MINI LOCO | C6: =SUMIF('MINI LOCO DATA APR - SEPT 2026'!$J$4:$J$422,$B6,'MINI LOCO DATA APR - SEPT 2026'!F$4:F$422) -> 821 | D6: =SUMIF('MINI LOCO DATA APR - SEPT 2026'!$J$4:$J$422,$B6,'MINI LOCO DATA APR - SEPT 2026'!G$4:G$422) -> 725 | E6: =SUMIF('MINI LOCO DATA APR - SEPT 2026'!$J$4:$J$422,$B6,'MINI LOCO DATA APR - SEPT 2026'!H$4:H$422) -> 96 | F6: =D6/C6 -> 0.88306943 | G6: =E6/C6 -> 0.11693057 | I6: Damages | J6: 16 | K6: =K5+J6 -> 176 | L6: =K6/$K$6 -> 1 | M6: =J6/$K$6 -> 0.090909091
B7: ICF MINI LOCO | C7: =SUMIF('MINI LOCO DATA APR - SEPT 2026'!$J$4:$J$422,$B7,'MINI LOCO DATA APR - SEPT 2026'!F$4:F$422) -> 287 | D7: =SUMIF('MINI LOCO DATA APR - SEPT 2026'!$J$4:$J$422,$B7,'MINI LOCO DATA APR - SEPT 2026'!G$4:G$422) -> 251 | E7: =SUMIF('MINI LOCO DATA APR - SEPT 2026'!$J$4:$J$422,$B7,'MINI LOCO DATA APR - SEPT 2026'!H$4:H$422) -> 36 | F7: =D7/C7 -> 0.87456446 | G7: =E7/C7 -> 0.12543554
B8: ICF EMU | C8: 124 | D8: 110 | E8: 14 | F8: =D8/C8 -> 0.88709677 | G8: =E8/C8 -> 0.11290323
B9: ICF MEMU | C9: =SUMIF('MINI LOCO DATA APR - SEPT 2026'!$J$4:$J$422,$B9,'MINI LOCO DATA APR - SEPT 2026'!F$4:F$422) -> 122 | D9: =SUMIF('MINI LOCO DATA APR - SEPT 2026'!$J$4:$J$422,$B9,'MINI LOCO DATA APR - SEPT 2026'!G$4:G$422) -> 113 | E9: =SUMIF('MINI LOCO DATA APR - SEPT 2026'!$J$4:$J$422,$B9,'MINI LOCO DATA APR - SEPT 2026'!H$4:H$422) -> 9 | F9: =D9/C9 -> 0.92622951 | G9: =E9/C9 -> 0.073770492
B10: DIESEL LOCO | C10: =SUMIF('MINI LOCO DATA APR - SEPT 2026'!$J$4:$J$422,$B10,'MINI LOCO DATA APR - SEPT 2026'!F$4:F$422) -> 34 | D10: =SUMIF('MINI LOCO DATA APR - SEPT 2026'!$J$4:$J$422,$B10,'MINI LOCO DATA APR - SEPT 2026'!G$4:G$422) -> 27 | E10: =SUMIF('MINI LOCO DATA APR - SEPT 2026'!$J$4:$J$422,$B10,'MINI LOCO DATA APR - SEPT 2026'!H$4:H$422) -> 7 | F10: =D10/C10 -> 0.79411765 | G10: =E10/C10 -> 0.20588235
B11: LAB LOCO | C11: =SUMIF('MINI LOCO DATA APR - SEPT 2026'!$J$4:$J$422,$B11,'MINI LOCO DATA APR - SEPT 2026'!F$4:F$422) -> 21 | D11: =SUMIF('MINI LOCO DATA APR - SEPT 2026'!$J$4:$J$422,$B11,'MINI LOCO DATA APR - SEPT 2026'!G$4:G$422) -> 16 | E11: =SUMIF('MINI LOCO DATA APR - SEPT 2026'!$J$4:$J$422,$B11,'MINI LOCO DATA APR - SEPT 2026'!H$4:H$422) -> 5 | F11: =D11/C11 -> 0.76190476 | G11: =E11/C11 -> 0.23809524
B12: HHP LOCO | C12: =SUMIF('MINI LOCO DATA APR - SEPT 2026'!$J$4:$J$422,$B12,'MINI LOCO DATA APR - SEPT 2026'!F$4:F$422) -> 2 | D12: =SUMIF('MINI LOCO DATA APR - SEPT 2026'!$J$4:$J$422,$B12,'MINI LOCO DATA APR - SEPT 2026'!G$4:G$422) -> 2 | E12: =SUMIF('MINI LOCO DATA APR - SEPT 2026'!$J$4:$J$422,$B12,'MINI LOCO DATA APR - SEPT 2026'!H$4:H$422) -> 0 | F12: =D12/C12 -> 1 | G12: =E12/C12 -> 0
B13: D9 LOCO | C13: =SUMIF('MINI LOCO DATA APR - SEPT 2026'!$J$4:$J$422,$B13,'MINI LOCO DATA APR - SEPT 2026'!F$4:F$422) -> 2 | D13: =SUMIF('MINI LOCO DATA APR - SEPT 2026'!$J$4:$J$422,$B13,'MINI LOCO DATA APR - SEPT 2026'!G$4:G$422) -> 2 | E13: =SUMIF('MINI LOCO DATA APR - SEPT 2026'!$J$4:$J$422,$B13,'MINI LOCO DATA APR - SEPT 2026'!H$4:H$422) -> 0 | F13: =D13/C13 -> 1 | G13: =E13/C13 -> 0
B14: Grand Total
B16: Sub Category of the problem | C16: No of issues Quantity | D16: Cumulative Quantity | E16: Cumulative (%) | F16: Defect Contribution (%)
B17: Loose Fitment | C17: 95 | D17: =C17 -> 95 | E17: =D17/$D$26 -> 0.53672316 | F17: =C17/$D$26 -> 0.53672316
B18: Wrong Operation | C18: 36 | D18: =C18+D17 -> 131 | E18: =D18/$D$26 -> 0.74011299 | F18: =C18/$D$26 -> 0.20338983
B19: Wires Interchanged | C19: 10 | D19: =D18+C19 -> 141 | E19: =D19/$D$26 -> 0.79661017 | F19: =C19/$D$26 -> 0.056497175
B20: Missing Component | C20: 8 | D20: =D19+C20 -> 149 | E20: =D20/$D$26 -> 0.84180791 | F20: =C20/$D$26 -> 0.04519774
B21: Interchange of PCBAs | C21: 6 | D21: =D20+C21 -> 155 | E21: =D21/$D$26 -> 0.87570621 | F21: =C21/$D$26 -> 0.033898305
B22: Paint Peel off | C22: 6 | D22: =D21+C22 -> 161 | E22: =D22/$D$26 -> 0.90960452 | F22: =C22/$D$26 -> 0.033898305
B23: Damaged component | C23: 5 | D23: =D22+C23 -> 166 | E23: =D23/$D$26 -> 0.93785311 | F23: =C23/$D$26 -> 0.028248588
B24: Scratches | C24: 5 | D24: =D23+C24 -> 171 | E24: =D24/$D$26 -> 0.96610169 | F24: =C24/$D$26 -> 0.028248588
B25: Wrong label | C25: 4 | D25: =D24+C25 -> 175 | E25: =D25/$D$26 -> 0.98870056 | F25: =C25/$D$26 -> 0.02259887
B26: Rust | C26: 2 | D26: =D25+C26 -> 177 | E26: =D26/$D$26 -> 1 | F26: =C26/$D$26 -> 0.011299435

Sheet MINI LOCO DATA APR - SEPT 2026
E2: TOTAL | F2: =SUM(F4:F1142) -> 1414 | G2: =SUM(G4:G1412) -> 1247 | H2: =SUM(H4:H1412) -> 167
A3: # | B3: Failure detected Area IPQC | C3: Failure Reported by (Name of QC Eng) | D3: Module Type /Project | E3: Part Number | F3: Production QTY ( Nos) | G3: Accepted QTY ( Nos) | H3: Defect QTY ( Nos) | I3: Date of occurrence of failures | J3: Name of Failed item (Main Unit / Module / Sub-module / component) | K3: Sl No of failed item | L3: "Observed Problem (First information Report)" | M3: Root Cause of failure | N3: Action to be taken (Corrective action) | O3: Responsible person | P3: Target Date | Q3: Preventive Action | R3: Responsible person.1 | S3: Target Date.1 | T3: Status (Issue Closed / Open) | U3: Sub Category | V3: Category of Problem | W3: Remarks, if any
A4: 1 | B4: IPQC | C4: M.Laharika | D4: WR ADI E70 | E4: 6000053421 | F4: 1 | G4: 1 | H4: 0 | I4: 46121 | J4: MINI LOCO | K4: 516301480426001 | L4: OK | O4: Kiran | P4: =I4+1 -> 46122 | R4: Kiran | S4: =I4+1 -> 46122 | T4: Closed
A5: 2 | B5: IPQC | C5: M. Laharika | D5: WR ADI E70 | E5: 6000053421 | F5: 1 | G5: 0 | H5: 1 | I5: 46121 | J5: MINI LOCO | K5: 516301480426002 | L5: Wrong Pin blocking for Voter Card J1 connecter | M5: Wrong pin blocking occurred because the J1 connector was not correctly aligned/positioned during assembly. The connector orientation and pin location were not adequately verified before fitment, allowing the wrong pin to get blocked | N5: 1. Removed the wrongly fitted/blocked J1 connector and corrected the pin position. 2. Inspected all J1 connectors in the affected lot for proper pin alignment. 3. Verified the corrected assembly with the drawing/specification and electrical continuity check. | O5: Kiran | P5: =I5+1 -> 46122 | Q5: 1. Added a clear J1 connector orientation/pin-marking at the assembly station. 2. Updated the work instruction with a reference picture showing the correct pin position. 3. Trained operators on correct J1 connector orientation and pin verification. 4. Introduced a first-piece verification and periodic pin-position check during production. | R5: Kiran | S5: =I5+1 -> 46122 | T5: Closed | U5: Wrong Operation | V5: Assembly Errors
A6: 3 | B6: IPQC | C6: M. Laharika | D6: WR ADI E70 | E6: 6000053421 | F6: 4 | G6: 4 | H6: 0 | I6: 46121 | J6: MINI LOCO | K6: 516301480426003-006 | L6: OK | O6: Kiran | P6: =I6+1 -> 46122 | R6: Kiran | S6: =I6+1 -> 46122 | T6: Closed
A7: 4 | B7: IPQC | C7: D.Srishanth Reddy & E.VAMSHI | D7: WR ADI E70 | E7: 6000053421 | F7: 19 | G7: 19 | H7: 0 | I7: 46122 | J7: MINI LOCO | K7: 516301480426007-025 | L7: OK | O7: Kiran | P7: =I7+1 -> 46123 | R7: Kiran | S7: =I7+1 -> 46123 | T7: Closed
A8: 5 | B8: IPQC | C8: M.Laharika & G.sravanthi | D8: BLW-2 E70 | E8: 6000053421 | F8: 6 | G8: 6 | H8: 0 | I8: 46141 | J8: MINI LOCO | K8: 516301480426026-031 | L8: OK | O8: Kiran | P8: =I8+1 -> 46142 | R8: Kiran | S8: =I8+1 -> 46142 | T8: Closed
A9: 6 | B9: IPQC | C9: M.Laharika & G.sravanthi | D9: BLW-2 E70 | E9: 6000053421 | F9: 1 | G9: 0 | H9: 1 | I9: 46141 | J9: MINI LOCO | K9: 516301480426032 | L9: Screw missing at 19"4U Rack Bottom Rack. | O9: Kiran | P9: =I9+1 -> 46142 | R9: Kiran | S9: =I9+1 -> 46142 | T9: Closed | U9: Missing Component | V9: Assembly Errors
A10: 7 | B10: IPQC | C10: M.Laharika & G.sravanthi | D10: BLW-2 E70 | E10: 6000053421 | F10: 1 | G10: 1 | H10: 0 | I10: 46141 | J10: MINI LOCO | K10: 516301480426033 | L10: OK | O10: Kiran | P10: =I10+1 -> 46142 | R10: Kiran | S10: =I10+1 -> 46142 | T10: Closed
A11: 8 | B11: IPQC | C11: M.Laharika & G.sravanthi | D11: BLW-2 E70 | E11: 6000053421 | F11: 1 | G11: 0 | H11: 1 | I11: 46141 | J11: MINI LOCO | K11: 516301480426034 | L11: Paint peel off on the front side of the door Top corrner | O11: Kiran | P11: =I11+1 -> 46142 | R11: Kiran | S11: =I11+1 -> 46142 | T11: Closed | U11: Paint Peel off | V11: Damages
A12: 9 | B12: IPQC | C12: M.Laharika & G.sravanthi | D12: BLW-2 E70 | E12: 6000053421 | F12: 1 | G12: 1 | H12: 0 | I12: 46141 | J12: MINI LOCO | K12: 516301480426035 | L12: OK | O12: Kiran | P12: =I12+1 -> 46142 | R12: Kiran | S12: =I12+1 -> 46142 | T12: Closed
A13: 10 | B13: IPQC | C13: M. Laharika | D13: BLW-2 E70 | E13: 6000053421 | F13: 5 | G13: 5 | H13: 0 | I13: 46170 | J13: MINI LOCO | K13: 516301480526074-078 | L13: OK | O13: Kiran | P13: =I13+1 -> 46171 | R13: Kiran | S13: =I13+1 -> 46171 | T13: Closed
A14: 11 | B14: IPQC | C14: M. Laharika | D14: BLW-2 E70 | E14: 6000053421 | F14: 1 | G14: 0 | H14: 1 | I14: 46170 | J14: MINI LOCO | K14: 516301480526079 | L14: Loose fitment at DPS-2 (M5*20mm)screws. Right middle of the Enclosure. | M14: Dps-2 screws were not tightened properly during assembly. Proper torque was not followed/verified by the operator. Final inspection did not identify the loose screws. | N14: Removed and refitted the loose screws properly. Tightened the DPS-2 screws to the specified torque. Checked all other heat sink screws for proper tightness and fitment. | O14: Kiran | P14: =I14+1 -> 46171 | Q14: Ensure the specified torque is followed during DPS-2 assembly. Use a calibrated torque screwdriver for tightening. Add heat sink screw torque verification to the assembly checklist. Conduct periodic operator training and final inspection to prevent recurrence. | R14: Kiran | S14: =I14+1 -> 46171 | T14: Closed | U14: Loose Fitment | V14: Assembly Errors
A15: 12 | B15: IPQC | C15: M. Laharika | D15: BLW-2 E70 | E15: 6000053421 | F15: 1 | G15: 1 | H15: 0 | I15: 46170 | J15: MINI LOCO | K15: 516301480526080 | L15: OK | O15: Kiran | P15: =I15+1 -> 46171 | R15: Kiran | S15: =I15+1 -> 46171 | T15: Closed
A16: 13 | B16: IPQC | C16: M. Laharika | D16: BLW-2 E70 | E16: 6000053421 | F16: 1 | G16: 0 | H16: 1 | I16: 46170 | J16: MINI LOCO | K16: 516301480526081 | L16: Loose fitment at DPS-2 (M5*20mm)screws. Left side top of the Enclosure. | M16: Dps-2 screws were not tightened properly during assembly. Proper torque was not followed/verified by the operator. Final inspection did not identify the loose screws. | N16: Removed and refitted the loose screws properly. Tightened the DPS-2 screws to the specified torque. Checked all other heat sink screws for proper tightness and fitment. | O16: Kiran | P16: =I16+1 -> 46171 | Q16: Ensure the specified torque is followed during DPS-2 assembly. Use a calibrated torque screwdriver for tightening. Add heat sink screw torque verification to the assembly checklist. Conduct periodic operator training and final inspection to prevent recurrence. | R16: Kiran | S16: =I16+1 -> 46171 | T16: Closed | U16: Loose Fitment | V16: Assembly Errors
A17: 14 | B17: IPQC | C17: M. Laharika | D17: BLW-2 E70 | E17: 6000053421 | F17: 2 | G17: 2 | H17: 0 | I17: 46170 | J17: MINI LOCO | K17: 516301480526082-083 | L17: OK | O17: Kiran | P17: =I17+1 -> 46171 | R17: Kiran | S17: =I17+1 -> 46171 | T17: Closed
A18: 15 | B18: IPQC | C18: M. Laharika | D18: BLW-2 E70 | E18: 6000053421 | F18: 1 | G18: 0 | H18: 1 | I18: 46170 | J18: MINI LOCO | K18: 516301480526084 | L18: Screws are missing at front side top of 4U rack | M18: Screws were not fitted properly during rack assembly. Operator missed the screw-fitting point during final assembly/inspection. No proper checklist or verification was followed after tightening the screws. | N18: Installed the missing screws immediately and tightened them properly. Checked all other screws on the front-side top rack for proper fitment and tightness. Confirmed the rack is securely assembled. | O18: Kiran | P18: =I18+1 -> 46171 | Q18: Introduce a screw-fitment checklist for every rack assembly. Operator to verify all screw locations before moving the rack to the next process. Add a final visual inspection for missing/loose screws. Provide awareness/training to operators on the importance of complete screw fitment. | R18: Kiran | S18: =I18+1 -> 46171 | T18: Closed | U18: Missing Component | V18: Assembly Errors
A19: 16 | B19: IPQC | C19: M. Laharika | D19: BLW-2 E70 | E19: 6000053421 | F19: 2 | G19: 2 | H19: 0 | I19: 46170 | J19: MINI LOCO | K19: 516301480526085-086 | L19: OK | O19: Kiran | P19: =I19+1 -> 46171 | R19: Kiran | S19: =I19+1 -> 46171 | T19: Closed
A20: 17 | B20: IPQC | C20: M. Laharika | D20: SWR IRCON CCB | E20: 6000053421 | F20: 2 | G20: 2 | H20: 0 | I20: 46177 | J20: MINI LOCO | K20: 516301480626087-088 | L20: OK | O20: Kiran | P20: =I20+1 -> 46178 | R20: Kiran | S20: =I20+1 -> 46178 | T20: Closed
A21: 18 | B21: IPQC | C21: M.Laharika & E. Vamshi | D21: PLW E70 | E21: 6000053421 | F21: 13 | G21: 13 | H21: 0 | I21: 46181 | J21: MINI LOCO | K21: 516301480626089-101 | L21: OK | O21: Kiran | P21: =I21+1 -> 46182 | R21: Kiran | S21: =I21+1 -> 46182 | T21: Closed
A22: 19 | B22: IPQC | C22: M.Laharika & E. Vamshi | D22: PLW CCB | E22: 6000053421 | F22: 2 | G22: 2 | H22: 0 | I22: 46182 | J22: MINI LOCO | K22: 516301480626102-103 | L22: OK | O22: Kiran | P22: =I22+1 -> 46183 | R22: Kiran | S22: =I22+1 -> 46183 | T22: Closed
A23: 20 | B23: IPQC | C23: M.Laharika & E. Vamshi | D23: PLW CCB | E23: 6000053421 | F23: 1 | G23: 0 | H23: 1 | I23: 46182 | J23: MINI LOCO | K23: 516301480626104 | L23: No pin cutting at PPC-1 & 2 PCBA card J11 & J12 Connecters | M23: Bent or missing pins due to handling, transport, or incorrect placement. Poor seating in the PCB through-hole or SMT pads can cause intermittent or absent connectivity. | N23: Reflow or manually resolder each pin on J11 and J12. Ensure proper wetting and solder fillet formation. | O23: Kiran | P23: =I23+1 -> 46183 | Q23: Introduce checklists in assembly SOPs to explicitly verify pin cutting steps. Implement mandatory inspection points: Before soldering, after pin cutting, and post-reflow. | R23: Kiran | S23: =I23+1 -> 46183 | T23: Closed | U23: Wrong Operation | V23: Assembly Errors
A24: 21 | B24: IPQC | C24: M. Laharika | D24: PLW CCB | E24: 6000053421 | F24: 3 | G24: 3 | H24: 0 | I24: 46182 | J24: MINI LOCO | K24: 516301480626105-107 | L24: OK | O24: Kiran | P24: =I24+1 -> 46183 | R24: Kiran | S24: =I24+1 -> 46183 | T24: Closed
A25: 22 | B25: IPQC | C25: M.Laharika & E. Vamshi | D25: PLW CCB | E25: 6000053421 | F25: 1 | G25: 0 | H25: 1 | I25: 46182 | J25: MINI LOCO | K25: 516301480626108 | L25: Loose Fitment 10.6'' 4U Rack Rear side Bottom screws. (M6*16mm). | O25: Kiran | P25: =I25+1 -> 46183 | R25: Kiran | S25: =I25+1 -> 46183 | T25: Closed | U25: Loose Fitment | V25: Assembly Errors
A26: 23 | B26: IPQC | C26: M. Laharika | D26: WR ADI CCB | E26: 6000053421 | F26: 3 | G26: 3 | H26: 0 | I26: 46183 | J26: MINI LOCO | K26: 516301480626109-111 | L26: OK | O26: Kiran | P26: =I26+1 -> 46184 | R26: Kiran | S26: =I26+1 -> 46184 | T26: Closed
A27: 24 | B27: IPQC | C27: M. Laharika | D27: CLW-3 E70 | E27: 6000053421 | F27: 1 | G27: 1 | H27: 0 | I27: 46186 | J27: MINI LOCO | K27: 516301480626112 | L27: OK | O27: Kiran | P27: =I27+1 -> 46187 | R27: Kiran | S27: =I27+1 -> 46187 | T27: Closed
A28: 25 | B28: IPQC | C28: M. Laharika | D28: CLW-3 E70 | E28: 6000053421 | F28: 1 | G28: 0 | H28: 1 | I28: 46186 | J28: MINI LOCO | K28: 516301480626113 | L28: Loose fitment 10.6" 4U Rack frount side Bottom All screw (M6*16mm). | O28: Kiran | P28: =I28+1 -> 46187 | R28: Kiran | S28: =I28+1 -> 46187 | T28: Closed | U28: Loose Fitment | V28: Assembly Errors
A29: 26 | B29: IPQC | C29: M. Laharika | D29: CLW-3 E70 | E29: 6000053421 | F29: 2 | G29: 2 | H29: 0 | I29: 46186 | J29: MINI LOCO | K29: 516301480626114-115 | L29: OK | O29: Kiran | P29: =I29+1 -> 46187 | R29: Kiran | S29: =I29+1 -> 46187 | T29: Closed
A30: 27 | B30: IPQC | C30: M. Laharika | D30: CLW-3 E70 | E30: 6000053421 | F30: 1 | G30: 0 | H30: 1 | I30: 46186 | J30: MINI LOCO | K30: 516301480626116 | L30: MIL Connecter Label missing at bottom of the Enclosure(CN1,CN2,MC10,MC9). | O30: Kiran | P30: =I30+1 -> 46187 | R30: Kiran | S30: =I30+1 -> 46187 | T30: Closed | U30: Missing Component | V30: Assembly Errors
A31: 28 | B31: IPQC | C31: M. Laharika | D31: CLW-3 E70 | E31: 6000053421 | F31: 5 | G31: 5 | H31: 0 | I31: 46188 | J31: MINI LOCO | K31: 516301480626117-121 | L31: OK | O31: Kiran | P31: =I31+1 -> 46189 | R31: Kiran | S31: =I31+1 -> 46189 | T31: Closed
A32: 29 | B32: IPQC | C32: M. Laharika | D32: CLW-3 E70 | E32: 6000053421 | F32: 1 | G32: 0 | H32: 1 | I32: 46188 | J32: MINI LOCO | K32: 516301480626122 | L32: MIL Connecter Label missing (CN1,CN2,MC10,MC9,MC6,MC7,MC22,MC3,MC5). | M32: During assembly, the MIL connector labels were missed due to improper identification/verification of connector labeling. The operator did not follow the label-checking process before moving the unit to the next stage. | N32: Installed the required labels on CN1, CN2, MC10, MC9, MC6, MC7, MC22, MC3 and MC5 as per the drawing/assembly specification. The labels were checked for correct position, readability and proper adhesion. | O32: Kiran | P32: =I32+1 -> 46189 | Q32: Added connector-label verification to the assembly inspection checklist. Operator was instructed to verify all connector labels against the drawing before final inspection. A 100% visual check of connector labeling will be carried out before dispatch. | R32: Kiran | S32: =I32+1 -> 46189 | T32: Closed | U32: Missing Component | V32: Assembly Errors
A33: 30 | B33: IPQC | C33: M. Laharika | D33: CLW-3 E70 | E33: 6000053421 | F33: 1 | G33: 0 | H33: 1 | I33: 46188 | J33: MINI LOCO | K33: 516301480626123 | L33: Rust observed at left side bottom of the Enclosure. | O33: Kiran | P33: =I33+1 -> 46189 | R33: Kiran | S33: =I33+1 -> 46189 | T33: Closed | U33: Rust | V33: Damages
A34: 31 | B34: IPQC | C34: M. Laharika | D34: CLW-3 E70 | E34: 6000053421 | F34: 8 | G34: 8 | H34: 0 | I34: 46188 | J34: MINI LOCO | K34: 516301480626124-131 | L34: OK | O34: Kiran | P34: =I34+1 -> 46189 | R34: Kiran | S34: =I34+1 -> 46189 | T34: Closed
A35: 32 | B35: IPQC | C35: M. Laharika | D35: WR ADI CCB | E35: 6000053421 | F35: 1 | G35: 0 | H35: 1 | I35: 46192 | J35: MINI LOCO | K35: 516301480626132 | L35: Wire interchanged at DPS-2 PCBA card J11 & J15 Connecter | M35: Wires at connectors J11 and J15 were interchanged during assembly due to improper wire identification and lack of verification before connection. The operator did not cross-check the wire position with the drawing/wiring schedule. Similar-looking wires/connectors increased the possibility of wrong insertion. | N35: Removed the wrongly connected wires and reconnected them correctly at J11 and J15 as per the approved drawing. Performed continuity and functional testing after correction. Inspected other wires on the same PCBA to confirm there were no similar issues. Briefed the concerned operator about correct wire identification and connection. | O35: Kiran | P35: =I35+1 -> 46193 | Q35: Provide clear wire labels/markers for J11 and J15 to avoid confusion. Introduce a 100% visual and point-to-point verification after wiring. Add a second-person inspection for critical connector wiring. Keep the latest approved wiring drawing available at the workstation. Provide refresher training to operators on connector identification and wiring verification. | R35: Kiran | S35: =I35+1 -> 46193 | T35: Closed | U35: Wires Interchanged | V35: Assembly Errors
A36: 33 | B36: IPQC | C36: M. Laharika | D36: WR ADI CCB | E36: 6000053421 | I36: 46192 | J36: MINI LOCO | K36: 516301480626132 | L36: Door issuse (glass is out side gas cut). | O36: Kiran | P36: =I36+1 -> 46193 | R36: Kiran | S36: =I36+1 -> 46193 | T36: Closed | U36: Wrong Operation | V36: Assembly Errors
A37: 34 | B37: IPQC | C37: M. Laharika | D37: WR ADI CCB | E37: 6000053421 | F37: 5 | G37: 5 | H37: 0 | I37: 46192 | J37: MINI LOCO | K37: 516301480626133-137 | L37: OK | O37: Kiran | P37: =I37+1 -> 46193 | R37: Kiran | S37: =I37+1 -> 46193 | T37: Closed
A38: 35 | B38: IPQC | C38: M. Laharika | D38: WR ADI CCB | E38: 6000053421 | F38: 1 | G38: 0 | H38: 1 | I38: 46192 | J38: MINI LOCO | K38: 516301480626138 | L38: Loose fitment earth cable Right side bottom of the Enclosure. | O38: Kiran | P38: =I38+1 -> 46193 | R38: Kiran | S38: =I38+1 -> 46193 | T38: Closed | U38: Loose Fitment | V38: Assembly Errors
A39: 36 | B39: IPQC | C39: M. Laharika | D39: CLW-3 CCB | E39: 6000053421 | F39: 2 | G39: 2 | H39: 0 | I39: 46192 | J39: MINI LOCO | K39: 516301480626139-140 | L39: OK | O39: Kiran | P39: =I39+1 -> 46193 | R39: Kiran | S39: =I39+1 -> 46193 | T39: Closed
A40: 37 | B40: IPQC | C40: M. Laharika | D40: CLW-3 E70 | E40: 6000053421 | F40: 1 | G40: 1 | H40: 0 | I40: 46192 | J40: MINI LOCO | K40: 516301480626141 | L40: OK | O40: Kiran | P40: =I40+1 -> 46193 | S40: =I40+1 -> 46193
A41: 38 | B41: IPQC | C41: M. Laharika | D41: CLW-3 E70 | E41: 6000053421 | F41: 1 | G41: 0 | H41: 1 | I41: 46192 | J41: MINI LOCO | K41: 516301480626142 | L41: Label erased at VTR-2 facia. | O41: Kiran | P41: =I41+1 -> 46193 | R41: Kiran | S41: =I41+1 -> 46193 | T41: Closed | U41: Wrong label | V41: Assembly Errors
...

Sheet CAB IP Summary – April to Septe
B1: CAB INPUT BOX Failure Summary – April to September _2026
B3: CAB INPUT BOX | C3: Total inspection Quantity | D3: Total Accepted Quantity | E3: Total Defect Quantity | F3: FTR % | G3: Defect % | I3: Category of the problem | J3: Defect QTY | K3: Cumulative QTY | L3: Cumulative (%) | M3: Defect Contribution (%)
B4: TYPE OF MODULE | C4: =SUM('CAB IP observations Apr-Sep 20'!F4,C5:C16) -> 1231 | D4: =SUM('CAB IP observations Apr-Sep 20'!G4,D5:D16) -> 1089 | E4: =SUM('CAB IP observations Apr-Sep 20'!H4,E5:E16) -> 142 | F4: =D4/C4 -> 0.88464663 | G4: =E4/C4 -> 0.11535337 | I4: Assembly Errors | J4: =SUMIF('CAB IP observations Apr-Sep 20'!V:V,I4,'CAB IP observations Apr-Sep 20'!H:H) -> 92 | K4: =J4 -> 92 | L4: =K4/$K$7 -> 0.64788732 | M4: =J4/$K$7 -> 0.64788732
B5: CAB INPUT BOX_E-70_4.0_(1.1V) | C5: 403 | D5: =SUMIF('CAB IP observations Apr-Sep 20'!J:J,B5,'CAB IP observations Apr-Sep 20'!G:G) -> 362 | E5: =SUMIF('CAB IP observations Apr-Sep 20'!J:J,B5,'CAB IP observations Apr-Sep 20'!H:H) -> 41 | F5: =D5/C5 -> 0.89826303 | G5: =E5/C5 -> 0.10173697 | I5: Enclosure Issues | J5: =SUMIF('CAB IP observations Apr-Sep 20'!V:V,I5,'CAB IP observations Apr-Sep 20'!H:H) -> 34 | K5: =K4+J5 -> 126 | L5: =K5/$K$7 -> 0.88732394 | M5: =J5/$K$7 -> 0.23943662
B6: CAB INPUT BOX_CCB_4.0_(1.1 V) | C6: =SUMIF('CAB IP observations Apr-Sep 20'!J:J,B6,'CAB IP observations Apr-Sep 20'!F:F) -> 265 | D6: =SUMIF('CAB IP observations Apr-Sep 20'!J:J,B6,'CAB IP observations Apr-Sep 20'!G:G) -> 230 | E6: =SUMIF('CAB IP observations Apr-Sep 20'!J:J,B6,'CAB IP observations Apr-Sep 20'!H:H) -> 35 | F6: =D6/C6 -> 0.86792453 | G6: =E6/C6 -> 0.13207547 | I6: Damages | J6: =SUMIF('CAB IP observations Apr-Sep 20'!V:V,I6,'CAB IP observations Apr-Sep 20'!H:H) -> 13 | K6: =K5+J6 -> 139 | L6: =K6/$K$7 -> 0.97887324 | M6: =J6/$K$7 -> 0.091549296
B7: CAB INPUT BOX_CONVENTIONAL_EMU | C7: =SUMIF('CAB IP observations Apr-Sep 20'!J:J,B7,'CAB IP observations Apr-Sep 20'!F:F) -> 134 | D7: =SUMIF('CAB IP observations Apr-Sep 20'!J:J,B7,'CAB IP observations Apr-Sep 20'!G:G) -> 114 | E7: =SUMIF('CAB IP observations Apr-Sep 20'!J:J,B7,'CAB IP observations Apr-Sep 20'!H:H) -> 20 | F7: =D7/C7 -> 0.85074627 | G7: =E7/C7 -> 0.14925373 | I7: Functional issues | J7: =SUMIF('CAB IP observations Apr-Sep 20'!V:V,I7,'CAB IP observations Apr-Sep 20'!H:H) -> 3 | K7: =K6+J7 -> 142 | L7: =K7/$K$7 -> 1 | M7: =J7/$K$7 -> 0.021126761
B8: CAB INPUT BOX_CONVENTIONAL_MEMU | C8: =SUMIF('CAB IP observations Apr-Sep 20'!J:J,B8,'CAB IP observations Apr-Sep 20'!F:F) -> 115 | D8: =SUMIF('CAB IP observations Apr-Sep 20'!J:J,B8,'CAB IP observations Apr-Sep 20'!G:G) -> 109 | E8: =SUMIF('CAB IP observations Apr-Sep 20'!J:J,B8,'CAB IP observations Apr-Sep 20'!H:H) -> 6 | F8: =D8/C8 -> 0.94782609 | G8: =E8/C8 -> 0.052173913
B9: CAB INPUT BOX_E-70_(4.0V) | C9: =SUMIF('CAB IP observations Apr-Sep 20'!J:J,B9,'CAB IP observations Apr-Sep 20'!F:F) -> 81 | D9: =SUMIF('CAB IP observations Apr-Sep 20'!J:J,B9,'CAB IP observations Apr-Sep 20'!G:G) -> 69 | E9: =SUMIF('CAB IP observations Apr-Sep 20'!J:J,B9,'CAB IP observations Apr-Sep 20'!H:H) -> 12 | F9: =D9/C9 -> 0.85185185 | G9: =E9/C9 -> 0.14814815
B10: CAB INPUT BOX_DIESEL | C10: =SUMIF('CAB IP observations Apr-Sep 20'!J:J,B10,'CAB IP observations Apr-Sep 20'!F:F) -> 56 | D10: =SUMIF('CAB IP observations Apr-Sep 20'!J:J,B10,'CAB IP observations Apr-Sep 20'!G:G) -> 55 | E10: =SUMIF('CAB IP observations Apr-Sep 20'!J:J,B10,'CAB IP observations Apr-Sep 20'!H:H) -> 1 | F10: =D10/C10 -> 0.98214286 | G10: =E10/C10 -> 0.017857143
B11: CAB INPUT BOX_3PHASE_MEMU | C11: =SUMIF('CAB IP observations Apr-Sep 20'!J:J,B11,'CAB IP observations Apr-Sep 20'!F:F) -> 62 | D11: =SUMIF('CAB IP observations Apr-Sep 20'!J:J,B11,'CAB IP observations Apr-Sep 20'!G:G) -> 55 | E11: =SUMIF('CAB IP observations Apr-Sep 20'!J:J,B11,'CAB IP observations Apr-Sep 20'!H:H) -> 7 | F11: =D11/C11 -> 0.88709677 | G11: =E11/C11 -> 0.11290323
B12: CAB INPUT BOX_EF12_E-70 | C12: =SUMIF('CAB IP observations Apr-Sep 20'!J:J,B12,'CAB IP observations Apr-Sep 20'!F:F) -> 40 | D12: =SUMIF('CAB IP observations Apr-Sep 20'!J:J,B12,'CAB IP observations Apr-Sep 20'!G:G) -> 28 | E12: =SUMIF('CAB IP observations Apr-Sep 20'!J:J,B12,'CAB IP observations Apr-Sep 20'!H:H) -> 12 | F12: =D12/C12 -> 0.7 | G12: =E12/C12 -> 0.3
B13: CAB INPUT BOX_IRAB_ELECTRIC | C13: =SUMIF('CAB IP observations Apr-Sep 20'!J:J,B13,'CAB IP observations Apr-Sep 20'!F:F) -> 40 | D13: =SUMIF('CAB IP observations Apr-Sep 20'!J:J,B13,'CAB IP observations Apr-Sep 20'!G:G) -> 36 | E13: =SUMIF('CAB IP observations Apr-Sep 20'!J:J,B13,'CAB IP observations Apr-Sep 20'!H:H) -> 4 | F13: =D13/C13 -> 0.9 | G13: =E13/C13 -> 0.1
B14: CAB INPUT BOX_3PHASE_EMU | C14: =SUMIF('CAB IP observations Apr-Sep 20'!J:J,B14,'CAB IP observations Apr-Sep 20'!F:F) -> 16 | D14: =SUMIF('CAB IP observations Apr-Sep 20'!J:J,B14,'CAB IP observations Apr-Sep 20'!G:G) -> 13 | E14: =SUMIF('CAB IP observations Apr-Sep 20'!J:J,B14,'CAB IP observations Apr-Sep 20'!H:H) -> 3 | F14: =D14/C14 -> 0.8125 | G14: =E14/C14 -> 0.1875
B15: CAB INPUT BOX_CCB_(4.0 V) | C15: =SUMIF('CAB IP observations Apr-Sep 20'!J:J,B15,'CAB IP observations Apr-Sep 20'!F:F) -> 18 | D15: =SUMIF('CAB IP observations Apr-Sep 20'!J:J,B15,'CAB IP observations Apr-Sep 20'!G:G) -> 17 | E15: =SUMIF('CAB IP observations Apr-Sep 20'!J:J,B15,'CAB IP observations Apr-Sep 20'!H:H) -> 1 | F15: =D15/C15 -> 0.94444444 | G15: =E15/C15 -> 0.055555556
B16: CAB INPUT BOX_D-9 | C16: =SUMIF('CAB IP observations Apr-Sep 20'!J:J,B16,'CAB IP observations Apr-Sep 20'!F:F) -> 1 | D16: =SUMIF('CAB IP observations Apr-Sep 20'!J:J,B16,'CAB IP observations Apr-Sep 20'!G:G) -> 1 | E16: =SUMIF('CAB IP observations Apr-Sep 20'!J:J,B16,'CAB IP observations Apr-Sep 20'!H:H) -> 0 | F16: =D16/C16 -> 1 | G16: =E16/C16 -> 0
B19: Sub Category of the problem | C19: No of issues Quantity | D19: Cumulative Quantity | E19: Cumulative (%) | F19: Defect Contribution (%)
B20: Loose Fitment | C20: 53 | D20: =C20 -> 53 | E20: =D20/$D$33 -> 0.37588652 | F20: =C20/$D$33 -> 0.37588652
B21: Locking Issues | C21: 34 | D21: =D20+C21 -> 87 | E21: =D21/$D$33 -> 0.61702128 | F21: =C21/$D$33 -> 0.24113475
B22: Hardware Damage | C22: 12 | D22: =D21+C22 -> 99 | E22: =D22/$D$33 -> 0.70212766 | F22: =C22/$D$33 -> 0.085106383
B23: Missing Component | C23: 12 | D23: =D22+C23 -> 111 | E23: =D23/$D$33 -> 0.78723404 | F23: =C23/$D$33 -> 0.085106383
B24: Wrong Label | C24: 9 | D24: =D23+C24 -> 120 | E24: =D24/$D$33 -> 0.85106383 | F24: =C24/$D$33 -> 0.063829787
B25: Wires Interchanged | C25: 8 | D25: =D24+C25 -> 128 | E25: =D25/$D$33 -> 0.90780142 | F25: =C25/$D$33 -> 0.056737589
B26: Component Issue | C26: 3 | D26: =D25+C26 -> 131 | E26: =D26/$D$33 -> 0.92907801 | F26: =C26/$D$33 -> 0.021276596
B27: Miss placement | C27: 2 | D27: =D26+C27 -> 133 | E27: =D27/$D$33 -> 0.94326241 | F27: =C27/$D$33 -> 0.014184397
B28: Missing of Operation | C28: 2 | D28: =D27+C28 -> 135 | E28: =D28/$D$33 -> 0.95744681 | F28: =C28/$D$33 -> 0.014184397
B29: Wrong component | C29: 2 | D29: =D28+C29 -> 137 | E29: =D29/$D$33 -> 0.97163121 | F29: =C29/$D$33 -> 0.014184397
B30: Loose connection | C30: 1 | D30: =D29+C30 -> 138 | E30: =D30/$D$33 -> 0.9787234 | F30: =C30/$D$33 -> 0.0070921986
B31: Paint peel off | C31: 1 | D31: =D30+C31 -> 139 | E31: =D31/$D$33 -> 0.9858156 | F31: =C31/$D$33 -> 0.0070921986
B32: Rust | C32: 1 | D32: =D31+C32 -> 140 | E32: =D32/$D$33 -> 0.9929078 | F32: =C32/$D$33 -> 0.0070921986
B33: Srew Stud issue | C33: 1 | D33: =D32+C33 -> 141 | E33: =D33/$D$33 -> 1 | F33: =C33/$D$33 -> 0.0070921986

Sheet CAB IP observations Apr-Sep 20
A1: ,
A2: CAB INPUT BOX Failure Report by QC Engineer at Factory from APRIL to SEPTEMBER -2026
E3: TOTAL | F3: =SUM(F4,F5:F796) -> 1231 | G3: =SUM(G4,G5:G796) -> 1089 | H3: =SUM(H4,H5:H796) -> 142
A4: Line # | B4: Failure detected Area (IPQC) | C4: Failure Reported by (Name of QC Eng) | D4: Project / Module Type | E4: Part Number | F4: Production QTY ( Nos) | G4: Accepted QTY ( Nos) | H4: Defect QTY ( Nos) | I4: Date of inspection | J4: Name of the item (Main, Unit / Module / Sub-module / component) | K4: Sl No of the item | L4: "Observed Problem (First information Report)" | M4: Root Cause of failure | N4: Action to be taken (Corrective action) | O4: Responsible person | P4: Target Date | Q4: Preventive Action | R4: Responsible person.1 | S4: Target Date.1 | T4: Status (Issue Closed / Open) | U4: Sub Category | V4: Category of Problem | W4: Remarks, if any
A5: 1 | B5: IPQC | C5: R.Navaneetha | D5: CLW-3 | E5: 6000054465 | F5: 2 | G5: 2 | H5: 0 | I5: 46122 | J5: CAB INPUT BOX_E-70_(4.0V) | K5: 516309050426001-002 | L5: OK | M5: OK | O5: Rajinikanth | R5: Rajinikanth | T5: Closed | U5: OK | V5: OK
A6: 2 | B6: IPQC | C6: R.Navaneetha | D6: CLW-3 | E6: 6000054465 | F6: 1 | G6: 0 | H6: 1 | I6: 46122 | J6: CAB INPUT BOX_E-70_(4.0V) | K6: 516309050426003 | L6: TB-1/2 & 2/2 wire interchanged. | M6: Operators unfamiliar with wire color codes. | N6: Wire corrected as per wiring drawing. | O6: Rajinikanth | P6: =I6+1 -> 46123 | Q6: Use color coding, diagrams to clearly indicate correct wiring sequences. | R6: Rajinikanth | S6: 46123 | T6: Closed | U6: Wires Interchanged | V6: Assembly Errors
A7: 3 | B7: IPQC | C7: R.Navaneetha | D7: CLW-3 | E7: 6000054465 | F7: 1 | G7: 1 | H7: 0 | I7: 46122 | J7: CAB INPUT BOX_E-70_(4.0V) | K7: 516309050426004 | L7: OK | M7: OK | O7: Rajinikanth | R7: Rajinikanth | T7: Closed | U7: OK | V7: OK
A8: 4 | B8: IPQC | C8: R.Navaneetha | D8: CLW-3 | E8: 6000054465 | F8: 7 | G8: 7 | H8: 0 | I8: 46123 | J8: CAB INPUT BOX_E-70_(4.0V) | K8: 516309050426005-011 | L8: OK | M8: OK | O8: Rajinikanth | R8: Rajinikanth | T8: Closed | U8: OK | V8: OK
A9: 5 | B9: IPQC | C9: R.Navaneetha | D9: CLW-3 | E9: 6000054465 | F9: 1 | G9: 0 | H9: 1 | I9: 46123 | J9: CAB INPUT BOX_E-70_(4.0V) | K9: 516309050426012 | L9: 17th & 18th wires interchanged in phoenix connector. | M9: Operators did not follow identification labels during assembly process | N9: Wire corrected as per wiring drawing. | O9: Rajinikanth | P9: =I9+1 -> 46124 | Q9: Provide work instructions and wiring drawings at work stations. | R9: Rajinikanth | S9: 46124 | T9: Closed | U9: Wires Interchanged | V9: Assembly Errors
A10: 6 | B10: IPQC | C10: R.Navaneetha | D10: CLW-3 | E10: 6000054465 | F10: 1 | G10: 1 | H10: 0 | I10: 46123 | J10: CAB INPUT BOX_E-70_(4.0V) | K10: 516309050426013 | L10: OK | M10: OK | O10: Rajinikanth | R10: Rajinikanth | T10: Closed | U10: OK | V10: OK
A11: 7 | B11: IPQC | C11: R.Navaneetha | D11: CLW-3 | E11: 6000054465 | F11: 1 | G11: 0 | H11: 1 | I11: 46123 | J11: CAB INPUT BOX_E-70_(4.0V) | K11: 516309050426014 | L11: WOAMA SIGNALLING RELAY (Q-51 Relay) not working. | M11: Faulty relay supplied by supplier. | N11: Faulty Q-51 relay was replaced with a working Q-51 relay. | O11: Rajinikanth | P11: =I11+1 -> 46124 | Q11: Supplier should ensure relay working condition before supplying relays | R11: Rajinikanth | S11: 46124 | T11: Closed | U11: Component Issue | V11: Functional issues
A12: 8 | B12: IPQC | C12: R.Navaneetha | D12: CLW-3 | E12: 6000054465 | F12: 5 | G12: 5 | H12: 0 | I12: 46123 | J12: CAB INPUT BOX_E-70_(4.0V) | K12: 516309050426015-019 | L12: OK | M12: OK | O12: Rajinikanth | R12: Rajinikanth | T12: Closed | U12: OK | V12: OK
A13: 9 | B13: IPQC | C13: R.Navaneetha | D13: CLW-3 | E13: 6000054465 | F13: 4 | G13: 4 | H13: 0 | I13: 46124 | J13: CAB INPUT BOX_E-70_(4.0V) | K13: 516309050426020-023 | L13: OK | M13: OK | O13: Rajinikanth | R13: Rajinikanth | T13: Closed | U13: OK | V13: OK
A14: 10 | B14: IPQC | C14: R.Navaneetha | D14: CLW-3 | E14: 6000054465 | F14: 2 | G14: 2 | H14: 0 | I14: 46127 | J14: CAB INPUT BOX_E-70_(4.0V) | K14: 516309050426024-025 | L14: OK | M14: OK | O14: Rajinikanth | R14: Rajinikanth | T14: Closed | U14: OK | V14: OK
A15: 11 | B15: IPQC | C15: R.Navaneetha | D15: CLW-3 | E15: 6000054465 | F15: 6 | G15: 6 | H15: 0 | I15: 46129 | J15: CAB INPUT BOX_E-70_(4.0V) | K15: 516309050426026-031 | L15: OK | M15: OK | O15: Rajinikanth | R15: Rajinikanth | T15: Closed | U15: OK | V15: OK
A16: 12 | B16: IPQC | C16: R.Navaneetha | D16: CLW-3 | E16: 6000054465 | F16: 4 | G16: 4 | H16: 0 | I16: 46130 | J16: CAB INPUT BOX_E-70_(4.0V) | K16: 516309050426036-039 | L16: OK | M16: OK | O16: Rajinikanth | R16: Rajinikanth | T16: Closed | U16: OK | V16: OK
A17: 13 | B17: IPQC | C17: R.Navaneetha | D17: CLW-3 | E17: 6000054465 | F17: 4 | G17: 4 | H17: 0 | I17: 46136 | J17: CAB INPUT BOX_E-70_(4.0V) | K17: 516309050526032-035 | L17: OK | M17: OK | O17: Rajinikanth | R17: Rajinikanth | T17: Closed | U17: OK | V17: OK
A18: 14 | B18: IPQC | C18: R.Navaneetha | D18: CLW-3 | E18: 6000054465 | F18: 1 | G18: 0 | H18: 1 | I18: 46136 | J18: CAB INPUT BOX_E-70_(4.0V) | K18: 516309050426040 | L18: Loose fitment of CN-1 110VDC 4-pin female MIL connector. | M18: Suitable tool is not used for fitting process of CN-1 110VDC 4-pin female connector. | N18: Tightened the connector with the buska tool as per the standards. | O18: Rajinikanth | P18: =I18+1 -> 46137 | Q18: Training should be given & proper tool should be provided to the operator by the Instructor. | R18: Rajinikanth | S18: 46137 | T18: Closed | U18: Loose Fitment | V18: Assembly Errors
A19: 15 | B19: IPQC | C19: R.Navaneetha | D19: CLW-3 | E19: 6000054465 | F19: 1 | G19: 1 | H19: 0 | I19: 46149 | J19: CAB INPUT BOX_E-70_(4.0V) | K19: 516309050526041 | L19: OK | M19: OK | O19: Rajinikanth | R19: Rajinikanth | T19: Closed | U19: OK | V19: OK
A20: 16 | B20: IPQC | C20: R.Navaneetha | D20: CLW-3 | E20: 6000054465 | F20: 1 | G20: 0 | H20: 1 | I20: 46149 | J20: CAB INPUT BOX_E-70_(4.0V) | K20: 516309050526042 | L20: Door play observed when it is locked. | M20: 1. Rough handling while assemblying. 2. No proper storage of Incoming material at stores. | N20: Replaced with another 24 pin phoenix connector. | O20: Rajinikanth | P20: =I20+1 -> 46150 | Q20: 1.Handle with care while operating 2.Maintain organized storage areas and ensure materials are securely stored in designated areas. | R20: Rajinikanth | S20: 46150 | T20: Closed | U20: Hardware Damage | V20: Damages
A21: 17 | B21: IPQC | C21: R.Navaneetha | D21: CLW-3 | E21: 6000054465 | F21: 1 | G21: 1 | H21: 0 | I21: 46149 | J21: CAB INPUT BOX_E-70_(4.0V) | K21: 516309050526043 | L21: OK | M21: OK | O21: Rajinikanth | R21: Rajinikanth | T21: Closed | U21: OK | V21: OK
A22: 18 | B22: IPQC | C22: R.Navaneetha | D22: CLW-3 | E22: 6000054465 | F22: 1 | G22: 0 | H22: 1 | I22: 46149 | J22: CAB INPUT BOX_E-70_(4.0V) | K22: 516309050526044 | L22: Loose fitment of M3*8mm allen head screw at EMI filter PCBA. | M22: 1.Suitable tool is not used for fixing M3*8mm allen head screws. 2.The instructor did not provide adequate training to use suitable tool for the fixing. | N22: Tightened the screw with the 3mm allen key tool as per its standards. | O22: Rajinikanth | P22: =I22+1 -> 46150 | Q22: 1.Proper tool should be provided to the operator by the Instructor. 2.Training should be given before performing the task. | R22: Rajinikanth | S22: 46150 | T22: Closed | U22: Loose Fitment | V22: Assembly Errors
A23: 19 | B23: IPQC | C23: R.Navaneetha | D23: CLW-3 | E23: 6000054465 | F23: 1 | G23: 1 | H23: 0 | I23: 46149 | J23: CAB INPUT BOX_E-70_(4.0V) | K23: 516309050526045 | L23: OK | M23: OK | O23: Rajinikanth | R23: Rajinikanth | T23: Closed | U23: OK | V23: OK
A24: 20 | B24: IPQC | C24: R.Navaneetha | D24: CLW-3 | E24: 6000054465 | F24: 13 | G24: 13 | H24: 0 | I24: 46154 | J24: CAB INPUT BOX_E-70_(4.0V) | K24: 516309050526046-058 | L24: OK | M24: OK | O24: Rajinikanth | R24: Rajinikanth | T24: Closed | U24: OK | V24: OK
A25: 21 | B25: IPQC | C25: R.Navaneetha | D25: BLW-1 | E25: 6000052972 | F25: 5 | G25: 5 | H25: 0 | I25: 46158 | J25: CAB INPUT BOX_DIESEL | K25: 516302060526001-005 | L25: OK | M25: OK | O25: Rajinikanth | R25: Rajinikanth | T25: Closed | U25: OK | V25: OK
A26: 22 | B26: IPQC | C26: R.Navaneetha | D26: BLW-1 | E26: 6000052972 | F26: 5 | G26: 5 | H26: 0 | I26: 46158 | J26: CAB INPUT BOX_DIESEL | K26: 516302060526001-005 | L26: OK | M26: OK | O26: Rajinikanth | R26: Rajinikanth | T26: Closed | U26: OK | V26: OK
A27: 23 | B27: IPQC | C27: R.Navaneetha | D27: CLW-3 | E27: 6000054465 | F27: 1 | G27: 0 | H27: 1 | I27: 46162 | J27: CAB INPUT BOX_E-70_(4.0V) | K27: 516309050526001 | L27: Door play observed when it is locked. | M27: Due to expansion of quater turn panel both locks are not fully locked. | N27: Adjusted the contraction of quater turn panel locks. | O27: Rajinikanth | P27: =I27+1 -> 46163 | Q27: Improve supplier quality (No issues at MCD supplier material). | R27: Rajinikanth | S27: 46163 | T27: Closed | U27: Locking Issues | V27: Enclosure Issues
A28: 24 | B28: IPQC | C28: R.Navaneetha | D28: CLW-3 | E28: 6000054465 | F28: 1 | G28: 0 | H28: 1 | I28: 46162 | J28: CAB INPUT BOX_E-70_(4.0V) | K28: 516309050526002 | L28: Door play observed when it is locked. | M28: Due to expansion of quater turn panel both locks are not fully locked. | N28: Adjusted the contraction of quater turn panel locks. | O28: Rajinikanth | P28: =I28+1 -> 46163 | Q28: Improve supplier quality (No issues at MCD supplier material). | R28: Rajinikanth | S28: 46163 | T28: Closed | U28: Locking Issues | V28: Enclosure Issues
A29: 25 | B29: IPQC | C29: R.Navaneetha | D29: CLW-3 | E29: 6000054465 | F29: 1 | G29: 0 | H29: 1 | I29: 46162 | J29: CAB INPUT BOX_E-70_(4.0V) | K29: 516309050526003 | L29: Door play observed when it is locked. | M29: Due to expansion of quater turn panel both locks are not fully locked. | N29: Adjusted the contraction of quater turn panel locks. | O29: Rajinikanth | P29: =I29+1 -> 46163 | Q29: Improve supplier quality (No issues at MCD supplier material). | R29: Rajinikanth | S29: 46163 | T29: Closed | U29: Locking Issues | V29: Enclosure Issues
A30: 26 | B30: IPQC | C30: R.Navaneetha | D30: CLW-3 | E30: 6000054465 | F30: 9 | G30: 9 | H30: 0 | I30: 46162 | J30: CAB INPUT BOX_E-70_(4.0V) | K30: 516309050526004-012 | L30: OK | M30: OK | O30: Rajinikanth | R30: Rajinikanth | T30: Closed | U30: OK | V30: OK
A31: 27 | B31: IPQC | C31: R.Navaneetha | D31: CLW-3 | E31: 6000054465 | F31: 1 | G31: 0 | H31: 1 | I31: 46162 | J31: CAB INPUT BOX_E-70_(4.0V) | K31: 516309050526013 | L31: Loose fitment of TCR at RLY (N/C)13th pin. | M31: 1.Suitable tool is not used for the fitment of traction cut off relay screw fixing. 2.The instructor did not provide adequate training for the operation. | N31: Tightened the pin as per its standards. | O31: Rajinikanth | P31: =I31+1 -> 46163 | Q31: 1.Proper tool should be provided to the operator by the Instructor. 2.Training should be given before performing the task. | R31: Rajinikanth | S31: 46163 | T31: Closed | U31: Loose Fitment | V31: Assembly Errors
A32: 28 | B32: IPQC | C32: R.Navaneetha | D32: CLW-3 | E32: 6000054463 | F32: 10 | G32: 10 | H32: 0 | I32: 46162 | J32: CAB INPUT BOX_CCB_(4.0 V) | K32: 516313050526001-010 | L32: OK | M32: OK | O32: Rajinikanth | R32: Rajinikanth | T32: Closed | U32: OK | V32: OK
A33: 29 | B33: IPQC | C33: R.Navaneetha | D33: CLW-3 | E33: 6000064637 | F33: 1 | G33: 0 | H33: 1 | I33: 46162 | J33: CAB INPUT BOX_CCB_4.0_(1.1 V) | K33: 516313050526011 | L33: Door play observed when it is locked. | M33: Due to expansion of quater turn panel both locks are not fully locked. | N33: Adjusted the contraction of quater turn panel locks. | O33: Rajinikanth | P33: =I33+1 -> 46163 | Q33: Improve supplier quality (No issues at MCD supplier material). | R33: Rajinikanth | S33: 46163 | T33: Closed | U33: Locking Issues | V33: Enclosure Issues
A34: 30 | B34: IPQC | C34: R.Navaneetha | D34: CLW-3 | E34: 6000064637 | F34: 1 | G34: 0 | H34: 1 | I34: 46162 | J34: CAB INPUT BOX_CCB_4.0_(1.1 V) | K34: 516313050526012 | L34: Door play observed when it is locked. | M34: Due to expansion of quater turn panel both locks are not fully locked. | N34: Adjusted the contraction of quater turn panel locks. | O34: Rajinikanth | P34: =I34+1 -> 46163 | Q34: Improve supplier quality (No issues at MCD supplier material). | R34: Rajinikanth | S34: 46163 | T34: Closed | U34: Locking Issues | V34: Enclosure Issues
A35: 31 | B35: IPQC | C35: D.Srishanth Reddy | D35: CLW-3 | E35: 6000064637 | F35: 1 | G35: 0 | H35: 1 | I35: 46162 | J35: CAB INPUT BOX_CCB_4.0_(1.1 V) | K35: 516313050526013 | M35: Due to expansion of quater turn panel both locks are not fully locked. | N35: Adjusted the contraction of quater turn panel locks. | O35: Rajinikanth | P35: =I35+1 -> 46163 | Q35: Improve supplier quality (No issues at MCD supplier material). | R35: Rajinikanth | S35: 46163 | T35: Closed | U35: Locking Issues | V35: Enclosure Issues
